[2025-07-30 15:13:19] エラー:
No such file: '../order_crypto.xlsx'
Traceback (most recent call last):
  File "C:\Users\koichi\Documents\MyDocuments\My_work\My_Programing_work\BitCoin\bitget_auto_rial\main.py", line 41, in main
    wb = app.books.open(excel_path)
  File "C:\Users\koichi\AppData\Local\Programs\Python\Python310\lib\site-packages\xlwings\main.py", line 5174, in open
    raise FileNotFoundError("No such file: '%s'" % fullname)
FileNotFoundError: No such file: '../order_crypto.xlsx'

[2025-07-30 15:15:09] エラー:
No such file: '../order_crypto.xlsx'
Traceback (most recent call last):
  File "C:\Users\koichi\Documents\MyDocuments\My_work\My_Programing_work\BitCoin\bitget_auto_rial\main.py", line 41, in main
    wb = app.books.open(excel_path)
  File "C:\Users\koichi\AppData\Local\Programs\Python\Python310\lib\site-packages\xlwings\main.py", line 5174, in open
    raise FileNotFoundError("No such file: '%s'" % fullname)
FileNotFoundError: No such file: '../order_crypto.xlsx'

400 Client Error: Bad Request for url: https://api.bitget.com/api/v2/mix/order/place-order
400 Client Error: Bad Request for url: https://api.bitget.com/api/v2/mix/order/place-order
400 Client Error: Bad Request for url: https://api.bitget.com/api/v2/mix/order/place-order
400 Client Error: Bad Request for url: https://api.bitget.com/api/v2/mix/order/place-order
400 Client Error: Bad Request for url: https://api.bitget.com/api/v2/mix/order/place-order
400 Client Error: Bad Request for url: https://api.bitget.com/api/v2/mix/order/place-order
400 Client Error: Bad Request for url: https://api.bitget.com/api/v2/mix/order/place-order
400 Client Error: Bad Request for url: https://api.bitget.com/api/v2/mix/order/place-order
[2025-08-01 20:19:13] エラー:
All candidate API paths failed
Traceback (most recent call last):
  File "C:\Users\koichi\Documents\MyDocuments\My_work\My_Programing_work\BitCoin\bitget_auto_rial\futuer_all_cancel.py", line 34, in cancel_all_orders_for_symbols
    res = client.cancel_all_orders(symbol=symbol, margin_coin="USDT")
  File "C:\Users\koichi\Documents\MyDocuments\My_work\My_Programing_work\BitCoin\bitget_auto_rial\bitget_client.py", line 71, in cancel_all_orders
    raise Exception("All candidate API paths failed")
Exception: All candidate API paths failed

[2025-08-02 08:33:01] エラー:
invalid literal for int() with base 10: '0.186310.186310.186310.186310.186310.186310.186310.186310.186310.186310.186310.186310.186310.186310.186310.186310.186310.186310.186310.186310.186310.186310.186310.186310.186310.186310.186310.186310.1
Traceback (most recent call last):
  File "C:\Users\koichi\Documents\MyDocuments\My_work\My_Programing_work\BitCoin\bitget_auto_rial\main.py", line 48, in main
    place_orders(
  File "C:\Users\koichi\Documents\MyDocuments\My_work\My_Programing_work\BitCoin\bitget_auto_rial\order_processor.py", line 41, in place_orders
    send_orders_for_sheet(client, wb, buy_sheet, price_places, volume_places)
  File "C:\Users\koichi\Documents\MyDocuments\My_work\My_Programing_work\BitCoin\bitget_auto_rial\order_processor.py", line 16, in send_orders_for_sheet
    price = adjust_price(price, price_places.get(symbol))
  File "C:\Users\koichi\Documents\MyDocuments\My_work\My_Programing_work\BitCoin\bitget_auto_rial\order_utils.py", line 20, in adjust_price
    adjusted = (int(price * factor)) / factor
ValueError: invalid literal for int() with base 10: '0.186310.186310.186310.186310.186310.186310.186310.186310.186310.186310.186310.186310.186310.186310.186310.186310.186310.186310.186310.186310.186310.186310.186310.186310.186310.186310.186310.186310.1

[2025-08-02 08:40:31] エラー:
invalid literal for int() with base 10: '0.186310.186310.186310.186310.186310.186310.186310.186310.186310.186310.186310.186310.186310.186310.186310.186310.186310.186310.186310.186310.186310.186310.186310.186310.186310.186310.186310.186310.1
Traceback (most recent call last):
  File "C:\Users\koichi\Documents\MyDocuments\My_work\My_Programing_work\BitCoin\bitget_auto_rial\main.py", line 48, in main
    place_orders(
  File "C:\Users\koichi\Documents\MyDocuments\My_work\My_Programing_work\BitCoin\bitget_auto_rial\order_processor.py", line 41, in place_orders
    send_orders_for_sheet(client, wb, buy_sheet, price_places, volume_places)
  File "C:\Users\koichi\Documents\MyDocuments\My_work\My_Programing_work\BitCoin\bitget_auto_rial\order_processor.py", line 16, in send_orders_for_sheet
    price = adjust_price(price, price_places.get(symbol))
  File "C:\Users\koichi\Documents\MyDocuments\My_work\My_Programing_work\BitCoin\bitget_auto_rial\order_utils.py", line 20, in adjust_price
    adjusted = (int(price * factor)) / factor
ValueError: invalid literal for int() with base 10: '0.186310.186310.186310.186310.186310.186310.186310.186310.186310.186310.186310.186310.186310.186310.186310.186310.186310.186310.186310.186310.186310.186310.186310.186310.186310.186310.186310.186310.1

[2025-08-05 08:28:41] エラー:
All candidate API paths failed
Traceback (most recent call last):
  File "C:\Users\koichi\Documents\MyDocuments\My_work\My_Programing_work\BitCoin\bitget_auto_rial\futuer_all_cancel.py", line 34, in cancel_all_orders_for_symbols
    res = client.cancel_all_orders(symbol=symbol, margin_coin="USDT")
  File "C:\Users\koichi\Documents\MyDocuments\My_work\My_Programing_work\BitCoin\bitget_auto_rial\bitget_client.py", line 71, in cancel_all_orders
    raise Exception("All candidate API paths failed")
Exception: All candidate API paths failed

[2025-08-06 11:25:27] エラー:
This object does not support enumeration
Traceback (most recent call last):
  File "C:\Users\koichi\AppData\Local\Temp\gen_py\3.13\00020813-0000-0000-C000-000000000046x0x1x9.py", line 36736, in __iter__
    ob = self._oleobj_.InvokeTypes(-4,LCID,2,(13, 10),())
pywintypes.com_error: (-2147418111, 'Call was rejected by callee.', None, None)

During handling of the above exception, another exception occurred:

Traceback (most recent call last):
  File "C:\Users\k\Documents\My_work\My_Programing_work\crypto\BitCoin\bitget_auto_rial\main.py", line 49, in main
    place_orders(
    ~~~~~~~~~~~~^
        client, wb, buy_sheet, sell_sheet, close_long_sheet, close_short_sheet
        ^^^^^^^^^^^^^^^^^^^^^^^^^^^^^^^^^^^^^^^^^^^^^^^^^^^^^^^^^^^^^^^^^^^^^^
    )
    ^
  File "C:\Users\k\Documents\My_work\My_Programing_work\crypto\BitCoin\bitget_auto_rial\order_processor.py", line 36, in place_orders
    sheet_names = [s.name for s in wb.sheets]
                                   ^^^^^^^^^
  File "C:\Users\koichi\AppData\Local\Programs\Python\Python313\Lib\site-packages\xlwings\main.py", line 69, in __iter__
    for impl in self.impl:
                ^^^^^^^^^
  File "C:\Users\koichi\AppData\Local\Programs\Python\Python313\Lib\site-packages\xlwings\_xlwindows.py", line 949, in __iter__
    for xl in self.xl:
              ^^^^^^^
  File "C:\Users\koichi\AppData\Local\Programs\Python\Python313\Lib\site-packages\xlwings\_xlwindows.py", line 259, in __iter__
    for v in self._inner:
             ^^^^^^^^^^^
  File "C:\Users\koichi\AppData\Local\Temp\gen_py\3.13\00020813-0000-0000-C000-000000000046x0x1x9.py", line 36738, in __iter__
    raise TypeError("This object does not support enumeration")
TypeError: This object does not support enumeration

[2025-08-06 11:31:34] エラー:
All candidate API paths failed
Traceback (most recent call last):
  File "C:\Users\k\Documents\My_work\My_Programing_work\crypto\BitCoin\bitget_auto_rial\futuer_all_cancel.py", line 34, in cancel_all_orders_for_symbols
    res = client.cancel_all_orders(symbol=symbol, margin_coin="USDT")
  File "C:\Users\k\Documents\My_work\My_Programing_work\crypto\BitCoin\bitget_auto_rial\bitget_client.py", line 71, in cancel_all_orders
    raise Exception("All candidate API paths failed")
Exception: All candidate API paths failed

[2025-08-06 11:31:55] エラー:
(-2147418111, 'Call was rejected by callee.', None, None)
Traceback (most recent call last):
  File "C:\Users\k\Documents\My_work\My_Programing_work\crypto\BitCoin\bitget_auto_rial\main.py", line 49, in main
    place_orders(
    ~~~~~~~~~~~~^
        client, wb, buy_sheet, sell_sheet, close_long_sheet, close_short_sheet
        ^^^^^^^^^^^^^^^^^^^^^^^^^^^^^^^^^^^^^^^^^^^^^^^^^^^^^^^^^^^^^^^^^^^^^^
    )
    ^
  File "C:\Users\k\Documents\My_work\My_Programing_work\crypto\BitCoin\bitget_auto_rial\order_processor.py", line 38, in place_orders
    price_places, volume_places = load_tick_sizes()
                                  ~~~~~~~~~~~~~~~^^
  File "C:\Users\k\Documents\My_work\My_Programing_work\crypto\BitCoin\bitget_auto_rial\order_reader.py", line 17, in load_tick_sizes
    sheet_names = [s.name for s in wb.sheets]
                                   ^^^^^^^^^
  File "C:\Users\koichi\AppData\Local\Programs\Python\Python313\Lib\site-packages\xlwings\main.py", line 69, in __iter__
    for impl in self.impl:
                ^^^^^^^^^
  File "C:\Users\koichi\AppData\Local\Programs\Python\Python313\Lib\site-packages\xlwings\_xlwindows.py", line 949, in __iter__
    for xl in self.xl:
              ^^^^^^^
  File "C:\Users\koichi\AppData\Local\Programs\Python\Python313\Lib\site-packages\xlwings\_xlwindows.py", line 259, in __iter__
    for v in self._inner:
             ^^^^^^^^^^^
  File "C:\Users\koichi\AppData\Local\Programs\Python\Python313\Lib\site-packages\win32com\client\util.py", line 103, in __next__
    return _get_good_object_(next(self._iter_), resultCLSID=self.resultCLSID)
                             ~~~~^^^^^^^^^^^^^
pywintypes.com_error: (-2147418111, 'Call was rejected by callee.', None, None)

[2025-08-06 11:34:06] エラー:
(-2147418111, 'Call was rejected by callee.', None, None)
Traceback (most recent call last):
  File "C:\Users\k\Documents\My_work\My_Programing_work\crypto\BitCoin\bitget_auto_rial\main.py", line 49, in main
    place_orders(
    ~~~~~~~~~~~~^
        client, wb, buy_sheet, sell_sheet, close_long_sheet, close_short_sheet
        ^^^^^^^^^^^^^^^^^^^^^^^^^^^^^^^^^^^^^^^^^^^^^^^^^^^^^^^^^^^^^^^^^^^^^^
    )
    ^
  File "C:\Users\k\Documents\My_work\My_Programing_work\crypto\BitCoin\bitget_auto_rial\order_processor.py", line 38, in place_orders
    price_places, volume_places = load_tick_sizes()
                                  ~~~~~~~~~~~~~~~^^
  File "C:\Users\k\Documents\My_work\My_Programing_work\crypto\BitCoin\bitget_auto_rial\order_reader.py", line 17, in load_tick_sizes
    sheet_names = [s.name for s in wb.sheets]
                                   ^^^^^^^^^
  File "C:\Users\koichi\AppData\Local\Programs\Python\Python313\Lib\site-packages\xlwings\main.py", line 69, in __iter__
    for impl in self.impl:
                ^^^^^^^^^
  File "C:\Users\koichi\AppData\Local\Programs\Python\Python313\Lib\site-packages\xlwings\_xlwindows.py", line 949, in __iter__
    for xl in self.xl:
              ^^^^^^^
  File "C:\Users\koichi\AppData\Local\Programs\Python\Python313\Lib\site-packages\xlwings\_xlwindows.py", line 259, in __iter__
    for v in self._inner:
             ^^^^^^^^^^^
  File "C:\Users\koichi\AppData\Local\Programs\Python\Python313\Lib\site-packages\win32com\client\util.py", line 103, in __next__
    return _get_good_object_(next(self._iter_), resultCLSID=self.resultCLSID)
                             ~~~~^^^^^^^^^^^^^
pywintypes.com_error: (-2147418111, 'Call was rejected by callee.', None, None)

[2025-08-06 11:39:10] エラー:
This object does not support enumeration
Traceback (most recent call last):
  File "C:\Users\koichi\AppData\Local\Temp\gen_py\3.13\00020813-0000-0000-C000-000000000046x0x1x9.py", line 36736, in __iter__
    ob = self._oleobj_.InvokeTypes(-4,LCID,2,(13, 10),())
pywintypes.com_error: (-2147418111, 'Call was rejected by callee.', None, None)

During handling of the above exception, another exception occurred:

Traceback (most recent call last):
  File "C:\Users\k\Documents\My_work\My_Programing_work\crypto\BitCoin\bitget_auto_rial\main.py", line 49, in main
    place_orders(
    ~~~~~~~~~~~~^
        client, wb, buy_sheet, sell_sheet, close_long_sheet, close_short_sheet
        ^^^^^^^^^^^^^^^^^^^^^^^^^^^^^^^^^^^^^^^^^^^^^^^^^^^^^^^^^^^^^^^^^^^^^^
    )
    ^
  File "C:\Users\k\Documents\My_work\My_Programing_work\crypto\BitCoin\bitget_auto_rial\order_processor.py", line 36, in place_orders
    sheet_names = [s.name for s in wb.sheets]
                                   ^^^^^^^^^
  File "C:\Users\koichi\AppData\Local\Programs\Python\Python313\Lib\site-packages\xlwings\main.py", line 69, in __iter__
    for impl in self.impl:
                ^^^^^^^^^
  File "C:\Users\koichi\AppData\Local\Programs\Python\Python313\Lib\site-packages\xlwings\_xlwindows.py", line 949, in __iter__
    for xl in self.xl:
              ^^^^^^^
  File "C:\Users\koichi\AppData\Local\Programs\Python\Python313\Lib\site-packages\xlwings\_xlwindows.py", line 259, in __iter__
    for v in self._inner:
             ^^^^^^^^^^^
  File "C:\Users\koichi\AppData\Local\Temp\gen_py\3.13\00020813-0000-0000-C000-000000000046x0x1x9.py", line 36738, in __iter__
    raise TypeError("This object does not support enumeration")
TypeError: This object does not support enumeration

[2025-08-06 11:41:30] エラー:
invalid literal for int() with base 10: '0.187130.187130.187130.187130.187130.187130.187130.187130.187130.187130.187130.187130.187130.187130.187130.187130.187130.187130.187130.187130.187130.187130.187130.187130.187130.187130.187130.187130.1
Traceback (most recent call last):
  File "C:\Users\k\Documents\My_work\My_Programing_work\crypto\BitCoin\bitget_auto_rial\main.py", line 51, in main
    place_orders(
    ~~~~~~~~~~~~^
        client, wb, buy_sheet, sell_sheet, close_long_sheet, close_short_sheet
        ^^^^^^^^^^^^^^^^^^^^^^^^^^^^^^^^^^^^^^^^^^^^^^^^^^^^^^^^^^^^^^^^^^^^^^
    )
    ^
  File "C:\Users\k\Documents\My_work\My_Programing_work\crypto\BitCoin\bitget_auto_rial\order_processor.py", line 41, in place_orders
    send_orders_for_sheet(client, wb, buy_sheet, price_places, volume_places)
    ~~~~~~~~~~~~~~~~~~~~~^^^^^^^^^^^^^^^^^^^^^^^^^^^^^^^^^^^^^^^^^^^^^^^^^^^^
  File "C:\Users\k\Documents\My_work\My_Programing_work\crypto\BitCoin\bitget_auto_rial\order_processor.py", line 16, in send_orders_for_sheet
    price = adjust_price(price, price_places.get(symbol))
  File "C:\Users\k\Documents\My_work\My_Programing_work\crypto\BitCoin\bitget_auto_rial\order_utils.py", line 20, in adjust_price
    adjusted = (int(price * factor)) / factor
                ~~~^^^^^^^^^^^^^^^^
ValueError: invalid literal for int() with base 10: '0.187130.187130.187130.187130.187130.187130.187130.187130.187130.187130.187130.187130.187130.187130.187130.187130.187130.187130.187130.187130.187130.187130.187130.187130.187130.187130.187130.187130.1

400 Client Error: Bad Request for url: https://api.bitget.com/api/v2/mix/order/place-order
400 Client Error: Bad Request for url: https://api.bitget.com/api/v2/mix/order/place-order
400 Client Error: Bad Request for url: https://api.bitget.com/api/v2/mix/order/place-order
400 Client Error: Bad Request for url: https://api.bitget.com/api/v2/mix/order/place-order
400 Client Error: Bad Request for url: https://api.bitget.com/api/v2/mix/order/place-order
[2025-08-07 11:57:27] エラー:
All candidate API paths failed
Traceback (most recent call last):
  File "C:\Users\k\Documents\My_work\My_Programing_work\crypto\BitCoin\bitget_auto_rial\futuer_all_cancel.py", line 34, in cancel_all_orders_for_symbols
    res = client.cancel_all_orders(symbol=symbol, margin_coin="USDT")
  File "C:\Users\k\Documents\My_work\My_Programing_work\crypto\BitCoin\bitget_auto_rial\bitget_client.py", line 71, in cancel_all_orders
    raise Exception("All candidate API paths failed")
Exception: All candidate API paths failed

[2025-08-10 03:43:31] エラー:
All candidate API paths failed
Traceback (most recent call last):
  File "C:\Users\koichi\Documents\MyDocuments\My_work\My_Programing_work\BitCoin\bitget_auto_rial\all_cancel_sub_account.py", line 35, in cancel_all_orders_for_symbols
    res = client.cancel_all_orders(symbol=symbol, margin_coin="USDT")
  File "C:\Users\koichi\Documents\MyDocuments\My_work\My_Programing_work\BitCoin\bitget_auto_rial\bitget_client.py", line 71, in cancel_all_orders
    raise Exception("All candidate API paths failed")
Exception: All candidate API paths failed

400 Client Error: Bad Request for url: https://api.bitget.com/api/v2/mix/order/place-order
400 Client Error: Bad Request for url: https://api.bitget.com/api/v2/mix/order/place-order
400 Client Error: Bad Request for url: https://api.bitget.com/api/v2/mix/order/place-order
400 Client Error: Bad Request for url: https://api.bitget.com/api/v2/mix/order/place-order
400 Client Error: Bad Request for url: https://api.bitget.com/api/v2/mix/order/place-order
400 Client Error: Bad Request for url: https://api.bitget.com/api/v2/mix/order/place-order
400 Client Error: Bad Request for url: https://api.bitget.com/api/v2/mix/order/place-order
400 Client Error: Bad Request for url: https://api.bitget.com/api/v2/mix/order/place-order
400 Client Error: Bad Request for url: https://api.bitget.com/api/v2/mix/order/place-order
400 Client Error: Bad Request for url: https://api.bitget.com/api/v2/mix/order/place-order
400 Client Error: Bad Request for url: https://api.bitget.com/api/v2/mix/order/place-order
400 Client Error: Bad Request for url: https://api.bitget.com/api/v2/mix/order/place-order
400 Client Error: Bad Request for url: https://api.bitget.com/api/v2/mix/order/place-order
400 Client Error: Bad Request for url: https://api.bitget.com/api/v2/mix/order/place-order
400 Client Error: Bad Request for url: https://api.bitget.com/api/v2/mix/order/place-order
400 Client Error: Bad Request for url: https://api.bitget.com/api/v2/mix/order/place-order
400 Client Error: Bad Request for url: https://api.bitget.com/api/v2/mix/order/place-order
400 Client Error: Bad Request for url: https://api.bitget.com/api/v2/mix/order/place-order
400 Client Error: Bad Request for url: https://api.bitget.com/api/v2/mix/order/place-order
400 Client Error: Bad Request for url: https://api.bitget.com/api/v2/mix/order/place-order
400 Client Error: Bad Request for url: https://api.bitget.com/api/v2/mix/order/place-order
400 Client Error: Bad Request for url: https://api.bitget.com/api/v2/mix/order/place-order
400 Client Error: Bad Request for url: https://api.bitget.com/api/v2/mix/order/place-order
400 Client Error: Bad Request for url: https://api.bitget.com/api/v2/mix/order/place-order
400 Client Error: Bad Request for url: https://api.bitget.com/api/v2/mix/order/place-order
400 Client Error: Bad Request for url: https://api.bitget.com/api/v2/mix/order/place-order
400 Client Error: Bad Request for url: https://api.bitget.com/api/v2/mix/order/place-order
400 Client Error: Bad Request for url: https://api.bitget.com/api/v2/mix/order/place-order
400 Client Error: Bad Request for url: https://api.bitget.com/api/v2/mix/order/place-order
400 Client Error: Bad Request for url: https://api.bitget.com/api/v2/mix/order/place-order
400 Client Error: Bad Request for url: https://api.bitget.com/api/v2/mix/order/place-order
400 Client Error: Bad Request for url: https://api.bitget.com/api/v2/mix/order/place-order
400 Client Error: Bad Request for url: https://api.bitget.com/api/v2/mix/order/place-order
400 Client Error: Bad Request for url: https://api.bitget.com/api/v2/mix/order/place-order
400 Client Error: Bad Request for url: https://api.bitget.com/api/v2/mix/order/place-order
400 Client Error: Bad Request for url: https://api.bitget.com/api/v2/mix/order/place-order
400 Client Error: Bad Request for url: https://api.bitget.com/api/v2/mix/order/place-order
400 Client Error: Bad Request for url: https://api.bitget.com/api/v2/mix/order/place-order
400 Client Error: Bad Request for url: https://api.bitget.com/api/v2/mix/order/place-order
400 Client Error: Bad Request for url: https://api.bitget.com/api/v2/mix/order/place-order
400 Client Error: Bad Request for url: https://api.bitget.com/api/v2/mix/order/place-order
400 Client Error: Bad Request for url: https://api.bitget.com/api/v2/mix/order/place-order
400 Client Error: Bad Request for url: https://api.bitget.com/api/v2/mix/order/place-order
400 Client Error: Bad Request for url: https://api.bitget.com/api/v2/mix/order/place-order
400 Client Error: Bad Request for url: https://api.bitget.com/api/v2/mix/order/place-order
400 Client Error: Bad Request for url: https://api.bitget.com/api/v2/mix/order/place-order
400 Client Error: Bad Request for url: https://api.bitget.com/api/v2/mix/order/place-order
400 Client Error: Bad Request for url: https://api.bitget.com/api/v2/mix/order/place-order
400 Client Error: Bad Request for url: https://api.bitget.com/api/v2/mix/order/place-order
400 Client Error: Bad Request for url: https://api.bitget.com/api/v2/mix/order/place-order
400 Client Error: Bad Request for url: https://api.bitget.com/api/v2/mix/order/place-order
400 Client Error: Bad Request for url: https://api.bitget.com/api/v2/mix/order/place-order
400 Client Error: Bad Request for url: https://api.bitget.com/api/v2/mix/order/place-order
400 Client Error: Bad Request for url: https://api.bitget.com/api/v2/mix/order/place-order
400 Client Error: Bad Request for url: https://api.bitget.com/api/v2/mix/order/place-order
400 Client Error: Bad Request for url: https://api.bitget.com/api/v2/mix/order/place-order
400 Client Error: Bad Request for url: https://api.bitget.com/api/v2/mix/order/place-order
400 Client Error: Bad Request for url: https://api.bitget.com/api/v2/mix/order/place-order
400 Client Error: Bad Request for url: https://api.bitget.com/api/v2/mix/order/place-order
400 Client Error: Bad Request for url: https://api.bitget.com/api/v2/mix/order/place-order
400 Client Error: Bad Request for url: https://api.bitget.com/api/v2/mix/order/place-order
400 Client Error: Bad Request for url: https://api.bitget.com/api/v2/mix/order/place-order
400 Client Error: Bad Request for url: https://api.bitget.com/api/v2/mix/order/place-order
400 Client Error: Bad Request for url: https://api.bitget.com/api/v2/mix/order/place-order
[2025-09-03 11:33:14] エラー:
(-2147418111, '呼び出し先が呼び出しを拒否しました。', None, None)
Traceback (most recent call last):
  File "C:\Users\k\Documents\My_work\My_Programing_work\crypto\BitCoin\bitget_auto_rial\main.py", line 45, in main
    place_orders(
    ~~~~~~~~~~~~^
        client,
        ^^^^^^^
    ...<2 lines>...
        close_long_sheet,
        ^^^^^^^^^^^^^^^^^
    )
    ^
  File "C:\Users\k\Documents\My_work\My_Programing_work\crypto\BitCoin\bitget_auto_rial\order_processor.py", line 45, in place_orders
    price_places, volume_places = load_tick_sizes()
                                  ~~~~~~~~~~~~~~~^^
  File "C:\Users\k\Documents\My_work\My_Programing_work\crypto\BitCoin\bitget_auto_rial\order_reader.py", line 17, in load_tick_sizes
    sheet_names = [s.name for s in wb.sheets]
                                   ^^^^^^^^^
  File "C:\Users\koichi\AppData\Local\Programs\Python\Python313\Lib\site-packages\xlwings\main.py", line 69, in __iter__
    for impl in self.impl:
                ^^^^^^^^^
  File "C:\Users\koichi\AppData\Local\Programs\Python\Python313\Lib\site-packages\xlwings\_xlwindows.py", line 949, in __iter__
    for xl in self.xl:
              ^^^^^^^
  File "C:\Users\koichi\AppData\Local\Programs\Python\Python313\Lib\site-packages\xlwings\_xlwindows.py", line 259, in __iter__
    for v in self._inner:
             ^^^^^^^^^^^
  File "C:\Users\koichi\AppData\Local\Programs\Python\Python313\Lib\site-packages\win32com\client\util.py", line 103, in __next__
    return _get_good_object_(next(self._iter_), resultCLSID=self.resultCLSID)
                             ~~~~^^^^^^^^^^^^^
pywintypes.com_error: (-2147418111, '呼び出し先が呼び出しを拒否しました。', None, None)

400 Client Error: Bad Request for url: https://api.bitget.com/api/v2/mix/order/place-order
400 Client Error: Bad Request for url: https://api.bitget.com/api/v2/mix/order/place-order
400 Client Error: Bad Request for url: https://api.bitget.com/api/v2/mix/order/place-order
[2025-09-03 11:48:23] エラー:
All candidate API paths failed
Traceback (most recent call last):
  File "C:\Users\k\Documents\My_work\My_Programing_work\crypto\BitCoin\bitget_auto_rial\futuer_all_cancel.py", line 33, in cancel_all_orders_for_symbols
    res = client.cancel_all_orders(symbol=symbol, margin_coin="USDT")
  File "C:\Users\k\Documents\My_work\My_Programing_work\crypto\BitCoin\bitget_auto_rial\bitget_client.py", line 73, in cancel_all_orders
    raise Exception("All candidate API paths failed")
Exception: All candidate API paths failed

[2025-09-03 11:53:53] エラー:
All candidate API paths failed
Traceback (most recent call last):
  File "C:\Users\k\Documents\My_work\My_Programing_work\crypto\BitCoin\bitget_auto_rial\futuer_all_cancel.py", line 33, in cancel_all_orders_for_symbols
    res = client.cancel_all_orders(symbol=symbol, margin_coin="USDT")
  File "C:\Users\k\Documents\My_work\My_Programing_work\crypto\BitCoin\bitget_auto_rial\bitget_client.py", line 73, in cancel_all_orders
    raise Exception("All candidate API paths failed")
Exception: All candidate API paths failed

[2025-09-03 11:54:40] エラー:
All candidate API paths failed
Traceback (most recent call last):
  File "C:\Users\k\Documents\My_work\My_Programing_work\crypto\BitCoin\bitget_auto_rial\futuer_all_cancel.py", line 33, in cancel_all_orders_for_symbols
    res = client.cancel_all_orders(symbol=symbol, margin_coin="USDT")
  File "C:\Users\k\Documents\My_work\My_Programing_work\crypto\BitCoin\bitget_auto_rial\bitget_client.py", line 73, in cancel_all_orders
    raise Exception("All candidate API paths failed")
Exception: All candidate API paths failed

400 Client Error: Bad Request for url: https://api.bitget.com/api/v2/mix/order/place-order
[2025-09-04 09:18:04] エラー:
All candidate API paths failed
Traceback (most recent call last):
  File "C:\Users\k\Documents\My_work\My_Programing_work\crypto\BitCoin\bitget_auto_rial\all_cancel_sub_account.py", line 35, in cancel_all_orders_for_symbols
    res = client.cancel_all_orders(symbol=symbol, margin_coin="USDT")
  File "C:\Users\k\Documents\My_work\My_Programing_work\crypto\BitCoin\bitget_auto_rial\bitget_client.py", line 73, in cancel_all_orders
    raise Exception("All candidate API paths failed")
Exception: All candidate API paths failed

400 Client Error: Bad Request for url: https://api.bitget.com/api/v2/mix/order/place-order
400 Client Error: Bad Request for url: https://api.bitget.com/api/v2/mix/order/place-order
[2025-09-05 09:18:28] エラー:
(-2147418111, '呼び出し先が呼び出しを拒否しました。', None, None)
Traceback (most recent call last):
  File "C:\Users\k\Documents\My_work\My_Programing_work\crypto\BitCoin\bitget_auto_rial\subaccount_futures.py", line 45, in main
    place_orders(
    ~~~~~~~~~~~~^
        client,
        ^^^^^^^
    ...<2 lines>...
        close_long_sheet,
        ^^^^^^^^^^^^^^^^^
    )
    ^
  File "C:\Users\k\Documents\My_work\My_Programing_work\crypto\BitCoin\bitget_auto_rial\order_processor.py", line 45, in place_orders
    price_places, volume_places = load_tick_sizes()
                                  ~~~~~~~~~~~~~~~^^
  File "C:\Users\k\Documents\My_work\My_Programing_work\crypto\BitCoin\bitget_auto_rial\order_reader.py", line 17, in load_tick_sizes
    sheet_names = [s.name for s in wb.sheets]
                                   ^^^^^^^^^
  File "C:\Users\koichi\AppData\Local\Programs\Python\Python313\Lib\site-packages\xlwings\main.py", line 69, in __iter__
    for impl in self.impl:
                ^^^^^^^^^
  File "C:\Users\koichi\AppData\Local\Programs\Python\Python313\Lib\site-packages\xlwings\_xlwindows.py", line 949, in __iter__
    for xl in self.xl:
              ^^^^^^^
  File "C:\Users\koichi\AppData\Local\Programs\Python\Python313\Lib\site-packages\xlwings\_xlwindows.py", line 259, in __iter__
    for v in self._inner:
             ^^^^^^^^^^^
  File "C:\Users\koichi\AppData\Local\Programs\Python\Python313\Lib\site-packages\win32com\client\util.py", line 103, in __next__
    return _get_good_object_(next(self._iter_), resultCLSID=self.resultCLSID)
                             ~~~~^^^^^^^^^^^^^
pywintypes.com_error: (-2147418111, '呼び出し先が呼び出しを拒否しました。', None, None)

[2025-09-06 09:11:13] エラー:
(-2147418111, '呼び出し先が呼び出しを拒否しました。', None, None)
Traceback (most recent call last):
  File "C:\Users\k\Documents\My_work\My_Programing_work\crypto\BitCoin\bitget_auto_rial\main.py", line 45, in main
    place_orders(
    ~~~~~~~~~~~~^
        client,
        ^^^^^^^
    ...<2 lines>...
        close_long_sheet,
        ^^^^^^^^^^^^^^^^^
    )
    ^
  File "C:\Users\k\Documents\My_work\My_Programing_work\crypto\BitCoin\bitget_auto_rial\order_processor.py", line 45, in place_orders
    price_places, volume_places = load_tick_sizes()
                                  ~~~~~~~~~~~~~~~^^
  File "C:\Users\k\Documents\My_work\My_Programing_work\crypto\BitCoin\bitget_auto_rial\order_reader.py", line 17, in load_tick_sizes
    sheet_names = [s.name for s in wb.sheets]
                                   ^^^^^^^^^
  File "C:\Users\koichi\AppData\Local\Programs\Python\Python313\Lib\site-packages\xlwings\main.py", line 69, in __iter__
    for impl in self.impl:
                ^^^^^^^^^
  File "C:\Users\koichi\AppData\Local\Programs\Python\Python313\Lib\site-packages\xlwings\_xlwindows.py", line 949, in __iter__
    for xl in self.xl:
              ^^^^^^^
  File "C:\Users\koichi\AppData\Local\Programs\Python\Python313\Lib\site-packages\xlwings\_xlwindows.py", line 259, in __iter__
    for v in self._inner:
             ^^^^^^^^^^^
  File "C:\Users\koichi\AppData\Local\Programs\Python\Python313\Lib\site-packages\win32com\client\util.py", line 103, in __next__
    return _get_good_object_(next(self._iter_), resultCLSID=self.resultCLSID)
                             ~~~~^^^^^^^^^^^^^
pywintypes.com_error: (-2147418111, '呼び出し先が呼び出しを拒否しました。', None, None)

[2025-09-06 09:17:50] エラー:
All candidate API paths failed
Traceback (most recent call last):
  File "C:\Users\k\Documents\My_work\My_Programing_work\crypto\BitCoin\bitget_auto_rial\all_cancel_sub_account.py", line 35, in cancel_all_orders_for_symbols
    res = client.cancel_all_orders(symbol=symbol, margin_coin="USDT")
  File "C:\Users\k\Documents\My_work\My_Programing_work\crypto\BitCoin\bitget_auto_rial\bitget_client.py", line 73, in cancel_all_orders
    raise Exception("All candidate API paths failed")
Exception: All candidate API paths failed

400 Client Error: Bad Request for url: https://api.bitget.com/api/v2/mix/order/place-order
400 Client Error: Bad Request for url: https://api.bitget.com/api/v2/mix/order/place-order
[2025-09-06 09:51:17] エラー:
All candidate API paths failed
Traceback (most recent call last):
  File "C:\Users\k\Documents\My_work\My_Programing_work\crypto\BitCoin\bitget_auto_rial\futuer_all_cancel.py", line 33, in cancel_all_orders_for_symbols
    res = client.cancel_all_orders(symbol=symbol, margin_coin="USDT")
  File "C:\Users\k\Documents\My_work\My_Programing_work\crypto\BitCoin\bitget_auto_rial\bitget_client.py", line 73, in cancel_all_orders
    raise Exception("All candidate API paths failed")
Exception: All candidate API paths failed

[2025-09-06 09:51:48] エラー:
(-2147418111, '呼び出し先が呼び出しを拒否しました。', None, None)
Traceback (most recent call last):
  File "C:\Users\k\Documents\My_work\My_Programing_work\crypto\BitCoin\bitget_auto_rial\main.py", line 45, in main
    place_orders(
    ~~~~~~~~~~~~^
        client,
        ^^^^^^^
    ...<2 lines>...
        close_long_sheet,
        ^^^^^^^^^^^^^^^^^
    )
    ^
  File "C:\Users\k\Documents\My_work\My_Programing_work\crypto\BitCoin\bitget_auto_rial\order_processor.py", line 45, in place_orders
    price_places, volume_places = load_tick_sizes()
                                  ~~~~~~~~~~~~~~~^^
  File "C:\Users\k\Documents\My_work\My_Programing_work\crypto\BitCoin\bitget_auto_rial\order_reader.py", line 17, in load_tick_sizes
    sheet_names = [s.name for s in wb.sheets]
                                   ^^^^^^^^^
  File "C:\Users\koichi\AppData\Local\Programs\Python\Python313\Lib\site-packages\xlwings\main.py", line 69, in __iter__
    for impl in self.impl:
                ^^^^^^^^^
  File "C:\Users\koichi\AppData\Local\Programs\Python\Python313\Lib\site-packages\xlwings\_xlwindows.py", line 949, in __iter__
    for xl in self.xl:
              ^^^^^^^
  File "C:\Users\koichi\AppData\Local\Programs\Python\Python313\Lib\site-packages\xlwings\_xlwindows.py", line 259, in __iter__
    for v in self._inner:
             ^^^^^^^^^^^
  File "C:\Users\koichi\AppData\Local\Programs\Python\Python313\Lib\site-packages\win32com\client\util.py", line 103, in __next__
    return _get_good_object_(next(self._iter_), resultCLSID=self.resultCLSID)
                             ~~~~^^^^^^^^^^^^^
pywintypes.com_error: (-2147418111, '呼び出し先が呼び出しを拒否しました。', None, None)

400 Client Error: Bad Request for url: https://api.bitget.com/api/v2/mix/order/place-order
400 Client Error: Bad Request for url: https://api.bitget.com/api/v2/mix/order/place-order
400 Client Error: Bad Request for url: https://api.bitget.com/api/v2/mix/order/place-order
400 Client Error: Bad Request for url: https://api.bitget.com/api/v2/mix/order/place-order
